Workbook

Sheet Task Brief
A1: T19 Event analytics and check-in tool
A2: Mini project | 30 marks | Build something with free LLM tools
A4: Task ID | B4: T19
A5: Task | B5: Event analytics and check-in tool
A6: Theme | B6: No-code apps & dashboards
A7: Suggested free tools | B7: Gemini Canvas, ChatGPT Canvas or Claude (free) to generate the app; Excel / Google Sheets to verify numbers
A8: What students do | B8: 1. Build a dashboard of registrations over time, source channel, no-show rate and NPS. 2. Add a check-in search screen by name or ID. 3. Find which channels bring attendees who actually show up. 4. Plan the marketing mix for next year's event.
A9: Deliverables | B9: Dashboard + check-in screen; channel analysis; plan; AI-use log
A10: Dataset in this file | B10: 500 registrations for a fictional business summit - 'Registrations' sheet: 500 rows x 12 columns - 'Event Info' sheet: 4 rows x 2 columns
A11: About the data | B11: All data is synthetic and created for teaching; companies, people and figures are fictional. Treat it as if it were real business data. If a 'Gold Labels (evaluation)' sheet is present, do NOT give it to the AI tool - use it only at the end to measure your accuracy.
A12: Team size | B12: Individual (or pairs if your faculty allows)
A13: Responsible AI rules | B13: Use only free tools; never paste real personal or confidential data into public AI tools; verify every number the AI gives you; disclose AI-generated content.
A14: Submission | B14: 1) Build link / file / screen recording 2) This workbook with your outputs added as new sheets 3) Completed 'AI Use Log' sheet (minimum 15 entries) 4) 3-5 page report with recommendation and reflection
A16: Evaluation rubric (30 marks)
A17: Criterion | B17: What is assessed | C17: Marks | D17: Excellent | E17: Good | F17: Fair | G17: Poor
A18: 1. Working build | B18: Tool / bot / app / automation works end to end on the provided data; link, file or screen recording submitted | C18: 8 | D18: Runs fully (7-8) | E18: Minor gaps (5-6) | F18: Partly working (3-4) | G18: Not working (0-2)
A19: 2. Correctness and verification | B19: Outputs checked against the data or gold labels; accuracy measured; errors found and fixed | C19: 7 | D19: Systematic checks with numbers (6-7) | E19: Some checks (4-5) | F19: Few checks (2-3) | G19: None (0-1)
A20: 3. Prompting and iteration | B20: Clear, structured prompts; at least 3 documented improvement rounds with reasons | C20: 5 | D20: Strong iteration (5) | E20: Some iteration (3-4) | F20: Mostly one-shot (2) | G20: No log (0-1)
A21: 4. Business insight and recommendation | B21: Specific, data-backed recommendation for the stated manager or customer | C21: 6 | D21: Actionable and quantified (6) | E21: Sound but generic (4-5) | F21: Descriptive only (2-3) | G21: Missing (0-1)
A22: 5. Documentation and reflection | B22: Complete AI-use log, limitations, responsible-AI notes and personal reflection | C22: 4 | D22: Complete and honest (4) | E22: Mostly complete (3) | F22: Thin (2) | G22: Missing (0-1)
A23: Total | C23: =SUM(C18:C22) -> 30

Sheet Registrations
A1: registration_id | B1: attendee_name | C1: gender | D1: city | E1: attendee_type | F1: heard_about_via | G1: registration_date | H1: early_bird | I1: fee_paid_inr | J1: checked_in | K1: sessions_selected | L1: nps_score_0to10
A2: REG0001 | B2: Ishaan Kulkarni | C2: Male | D2: Lucknow | E2: Student | F2: WhatsApp group | G2: 45978 | H2: Yes | I2: 399.2 | J2: Yes | K2: Startup pitch
A3: REG0002 | B3: Harsh Khan | C3: Male | D3: Kolkata | E3: Student | F3: Friend referral | G3: 46002 | H3: No | I3: 499 | J3: Yes | K3: Analytics bootcamp
A4: REG0003 | B4: Swati Mehta | C4: Female | D4: Kolkata | E4: Student | F4: College mailer | G4: 45997 | H4: No | I4: 499 | J4: Yes | K4: Analytics bootcamp, Networking lunch | L4: 9
A5: REG0004 | B5: Arjun Pillai | C5: Male | D5: Bengaluru | E5: Student | F5: Website | G5: 45975 | H5: Yes | I5: 399.2 | J5: Yes | K5: Fintech panel, Startup pitch
A6: REG0005 | B6: Neha Pawar | C6: Female | D6: Chandigarh | E6: Student | F6: WhatsApp group | G6: 45971 | H6: Yes | I6: 399.2 | J6: Yes | K6: Analytics bootcamp | L6: 7
A7: REG0006 | B7: Arjun Singh | C7: Male | D7: Kolkata | E7: Professional | F7: Instagram | G7: 46001 | H7: No | I7: 1999 | J7: Yes | K7: Marketing workshop | L7: 7
A8: REG0007 | B8: Tanvi D'Souza | C8: Female | D8: Patna | E8: Student | F8: LinkedIn | G8: 46003 | H8: No | I8: 499 | J8: Yes | K8: Analytics bootcamp, Fintech panel | L8: 7
A9: REG0008 | B9: Sakshi Desai | C9: Female | D9: Surat | E9: Student | F9: WhatsApp group | G9: 46011 | H9: No | I9: 499 | J9: Yes | K9: Marketing workshop | L9: 6
A10: REG0009 | B10: Siddharth Khan | C10: Male | D10: Kolkata | E10: Faculty | F10: WhatsApp group | G10: 45965 | H10: Yes | I10: 0 | J10: No | K10: GenAI keynote
A11: REG0010 | B11: Gurpreet Mishra | C11: Male | D11: Mumbai | E11: Professional | F11: Friend referral | G11: 45970 | H11: Yes | I11: 1599.2 | J11: Yes | K11: Analytics bootcamp, Fintech panel, Networking lunch | L11: 7
A12: REG0011 | B12: Arjun Kulkarni | C12: Male | D12: Chennai | E12: Student | F12: College mailer | G12: 46001 | H12: No | I12: 499 | J12: Yes | K12: Analytics bootcamp, Fintech panel, Startup pitch
A13: REG0012 | B13: Priya Kulkarni | C13: Female | D13: Jaipur | E13: Student | F13: WhatsApp group | G13: 45995 | H13: No | I13: 499 | J13: Yes | K13: Networking lunch, Startup pitch
A14: REG0013 | B14: Tushar Khan | C14: Male | D14: Chandigarh | E14: Startup Founder | F14: LinkedIn | G14: 45967 | H14: Yes | I14: 799.2 | J14: Yes | K14: Analytics bootcamp, Fintech panel
A15: REG0014 | B15: Pallavi Fernandes | C15: Female | D15: Mumbai | E15: Startup Founder | F15: Website | G15: 45977 | H15: Yes | I15: 799.2 | J15: Yes | K15: Analytics bootcamp, Startup pitch
A16: REG0015 | B16: Gauri Verma | C16: Female | D16: Ahmedabad | E16: Professional | F16: Instagram | G16: 46009 | H16: No | I16: 1999 | J16: No | K16: Fintech panel, GenAI keynote
A17: REG0016 | B17: Nikhil Singh | C17: Male | D17: Nagpur | E17: Professional | F17: Friend referral | G17: 45981 | H17: Yes | I17: 1599.2 | J17: Yes | K17: Marketing workshop | L17: 10
A18: REG0017 | B18: Thomas Pawar | C18: Male | D18: Bengaluru | E18: Student | F18: Friend referral | G18: 45983 | H18: Yes | I18: 399.2 | J18: Yes | K18: Marketing workshop, Startup pitch
A19: REG0018 | B19: Sakshi D'Souza | C19: Female | D19: Indore | E19: Student | F19: Instagram | G19: 45982 | H19: Yes | I19: 399.2 | J19: Yes | K19: Fintech panel | L19: 7
A20: REG0019 | B20: Rahul Joshi | C20: Male | D20: Patna | E20: Student | F20: Website | G20: 45998 | H20: No | I20: 499 | J20: Yes | K20: GenAI keynote
A21: REG0020 | B21: Fatima Reddy | C21: Female | D21: Bengaluru | E21: Professional | F21: Website | G21: 45971 | H21: Yes | I21: 1599.2 | J21: Yes | K21: Fintech panel, Marketing workshop, Networking lunch | L21: 6
A22: REG0021 | B22: Harpreet Chatterjee | C22: Male | D22: Guwahati | E22: Professional | F22: Friend referral | G22: 46013 | H22: No | I22: 1999 | J22: Yes | K22: Networking lunch | L22: 9
A23: REG0022 | B23: Rohan Shah | C23: Male | D23: Guwahati | E23: Student | F23: WhatsApp group | G23: 45995 | H23: No | I23: 499 | J23: Yes | K23: Networking lunch | L23: 8
A24: REG0023 | B24: Simran Agarwal | C24: Female | D24: Jaipur | E24: Professional | F24: Website | G24: 46009 | H24: No | I24: 1999 | J24: Yes | K24: Fintech panel, Startup pitch
A25: REG0024 | B25: Fatima Das | C25: Female | D25: Patna | E25: Student | F25: Friend referral | G25: 46021 | H25: No | I25: 499 | J25: No | K25: Analytics bootcamp, Networking lunch
A26: REG0025 | B26: Varun Khan | C26: Male | D26: Nagpur | E26: Student | F26: Friend referral | G26: 45968 | H26: Yes | I26: 399.2 | J26: Yes | K26: Startup pitch | L26: 9
A27: REG0026 | B27: Aarav Das | C27: Male | D27: Mumbai | E27: Student | F27: WhatsApp group | G27: 45999 | H27: No | I27: 499 | J27: No | K27: Analytics bootcamp, GenAI keynote, Startup pitch
A28: REG0027 | B28: Harleen Gupta | C28: Female | D28: Delhi | E28: Professional | F28: College mailer | G28: 45972 | H28: Yes | I28: 1599.2 | J28: Yes | K28: GenAI keynote, Networking lunch
A29: REG0028 | B29: Deepika Das | C29: Female | D29: Nagpur | E29: Professional | F29: Instagram | G29: 45987 | H29: Yes | I29: 1599.2 | J29: Yes | K29: Analytics bootcamp, Startup pitch | L29: 6
A30: REG0029 | B30: Vivaan Fernandes | C30: Male | D30: Kolkata | E30: Student | F30: Instagram | G30: 45983 | H30: Yes | I30: 399.2 | J30: Yes | K30: Analytics bootcamp, Fintech panel, Startup pitch | L30: 10
A31: REG0030 | B31: Swati Banerjee | C31: Female | D31: Ahmedabad | E31: Student | F31: Friend referral | G31: 46011 | H31: No | I31: 499 | J31: Yes | K31: Analytics bootcamp, GenAI keynote, Networking lunch
A32: REG0031 | B32: Pranav Joshi | C32: Male | D32: Patna | E32: Student | F32: Website | G32: 45979 | H32: Yes | I32: 399.2 | J32: Yes | K32: GenAI keynote | L32: 6
A33: REG0032 | B33: Farhan Iyer | C33: Male | D33: Mumbai | E33: Faculty | F33: WhatsApp group | G33: 46012 | H33: No | I33: 0 | J33: Yes | K33: Startup pitch | L33: 6
A34: REG0033 | B34: Harleen Kulkarni | C34: Female | D34: Patna | E34: Professional | F34: LinkedIn | G34: 46010 | H34: No | I34: 1999 | J34: Yes | K34: Fintech panel, GenAI keynote
A35: REG0034 | B35: Gauri Fernandes | C35: Female | D35: Kolkata | E35: Faculty | F35: LinkedIn | G35: 46005 | H35: No | I35: 0 | J35: No | K35: Fintech panel, Marketing workshop, Networking lunch
A36: REG0035 | B36: Kabir Kulkarni | C36: Male | D36: Surat | E36: Professional | F36: LinkedIn | G36: 45995 | H36: No | I36: 1999 | J36: Yes | K36: Analytics bootcamp, Startup pitch | L36: 8
A37: REG0036 | B37: Anjali Pillai | C37: Female | D37: Patna | E37: Student | F37: Instagram | G37: 46005 | H37: No | I37: 499 | J37: Yes | K37: Analytics bootcamp, GenAI keynote, Networking lunch
A38: REG0037 | B38: Harsh Kaur | C38: Male | D38: Kolkata | E38: Professional | F38: College mailer | G38: 46018 | H38: No | I38: 1999 | J38: No | K38: Fintech panel, GenAI keynote, Networking lunch
A39: REG0038 | B39: Pranav Menon | C39: Male | D39: Delhi | E39: Startup Founder | F39: WhatsApp group | G39: 45987 | H39: Yes | I39: 799.2 | J39: Yes | K39: Analytics bootcamp
A40: REG0039 | B40: Thomas Nair | C40: Male | D40: Kolkata | E40: Professional | F40: College mailer | G40: 45967 | H40: Yes | I40: 1599.2 | J40: Yes | K40: Networking lunch
...

Sheet Event Info
A1: item | B1: value
A2: Event | B2: InnoVista Business Summit 2026 (fictional)
A3: Date | B3: 3 January 2026
A4: Venue | B4: Sahyadri School of Business auditorium, capacity 450
A5: Fees | B5: Student 499, Professional 1,999, Founder 999, Faculty free; 20% early-bird discount before 1 Dec

Sheet Data Dictionary
A1: sheet | B1: column | C1: data_type | D1: example_value | E1: non_empty_values | F1: distinct_values
A2: Registrations | B2: registration_id | C2: Text | D2: REG0001 | E2: 500 | F2: 500
A3: Registrations | B3: attendee_name | C3: Text | D3: Ishaan Kulkarni | E3: 500 | F3: 430
A4: Registrations | B4: gender | C4: Text | D4: Male | E4: 500 | F4: 2
A5: Registrations | B5: city | C5: Text | D5: Lucknow | E5: 500 | F5: 20
A6: Registrations | B6: attendee_type | C6: Text | D6: Student | E6: 500 | F6: 4
A7: Registrations | B7: heard_about_via | C7: Text | D7: WhatsApp group | E7: 500 | F7: 6
A8: Registrations | B8: registration_date | C8: Date/time | D8: 2025-11-17 | E8: 500 | F8: 60
A9: Registrations | B9: early_bird | C9: Text | D9: Yes | E9: 500 | F9: 2
A10: Registrations | B10: fee_paid_inr | C10: Decimal number | D10: 399.20000000000005 | E10: 500 | F10: 7
A11: Registrations | B11: checked_in | C11: Text | D11: Yes | E11: 500 | F11: 2
A12: Registrations | B12: sessions_selected | C12: Text | D12: Startup pitch | E12: 500 | F12: 41
A13: Registrations | B13: nps_score_0to10 | C13: Decimal number | D13: 9.0 | E13: 255 | F13: 5
... A15: Event Info | B15: value | C15: Text | D15: InnoVista Business Summit 2026 (fictional) | E15: 4 | F15: 4

Sheet AI Use Log
A2: Evidence = shared chat link or screenshot file name. Keep rejected outputs too - they earn marks under 'Prompting and iteration'.
A3: # | B3: date | C3: tool | D3: model / mode | E3: settings used (if any) | F3: prompt (exact text) | G3: what the output did well / badly | H3: what I changed next and why | I3: kept or rejected | J3: evidence link / file
A4: 1 | B4: 46034 | C4: Gemini (free) | D4: Gemini app, default | E4: - | F4: You are a business analyst. Using the attached sheet for 'Event analytics and check-in tool', list the first 3 steps to build it and what could go wrong. | G4: Clear steps, but assumed a column that does not exist | H4: Told it the exact column names and asked it to recheck | I4: Rejected | J4: screenshot_01.png
A5: 2 | B5: 46267 | C5: Claude | D5: Claude | F5: Act as a senior data analyst, dashboard developer, and academic project mentor. Build and refine the Event Analytics and Check-in Tool for the InnoVista Business Summit 2026 (fictional event, 3 January 2026, venue capacity 450, fees: Student ₹499, Professional ₹1,999, Startup Founder ₹999, Faculty free, with a 20% early-bird discount before 1 December 2025), using ONLY the uploaded data and the requirements in the Task Brief. The final audience is the event's Head of Marketing, so every insight must be specific, quantified, and traceable to the data. Rules for the whole conversation: use only the uploaded data; do not fabricate data; do not silently change definitions; do not overwrite working functionality unnecessarily; if a requirement is ambiguous, state your assumption in one line and proceed; prioritize correctness over visual decoration. We will work one phase at a time. Complete only the phase I give you, then stop.Definitions, which you must not change silently: Attendance rate = checked_in "Yes" divided by total registrations. No-show rate = checked_in "No" divided by total registrations. NPS uses nps_score_0to10: Promoters = 9–10, Passives = 7–8, Detractors = 0–6. Exclude missing scores from the denominator and never treat blanks as zero. NPS = % Promoters minus % Detractors among valid responses. Always show the valid response count (n). attendee_name is not unique, so registration_id is the unique key. sessions_selected holds several sessions in one cell separated by commas. The Registrations columns are A to L in order: registration_id, attendee_name, gender, city, attendee_type, heard_about_via, registration_date, early_bird, fee_paid_inr, checked_in, sessions_selected, nps_score_0to10. Phase 1, inspection: Inspect the uploaded data. Tell me the exact columns and row count you actually see, the field meanings, data types, missing values, duplicates, invalid or inconsistent values (for example fee versus attendee_type and early_bird, or dates outside the expected range), and the relationships between fields. Do not invent any values or fields that are not present. Do not build anything yet. Then stop. | G5: Reported exactly 500 rows and 12 columns, 0 duplicate registration IDs, and 62 repeated names. Found all fees consistent with attendee type and early-bird, and all dates inside 1 Nov to 30 Dec 2025. Noticed there is no Gold Labels sheet. It rounded NPS to "about +24.0" from rounded percentages (the exact figure is 23.92), and the answer was long. | H5: I asked for the baseline KPIs with pasteable Excel formulas so I could check every number myself. | I5: Kept | J5: Sheet1!A1
A6: 3 | B6: 46267 | C6: Claude | D6: Claude | F6: Continue. Phase 2, baseline and verification formulas: Calculate the baseline KPIs: total registrations, total check-ins, total no-shows, attendance rate, no-show rate, total revenue, NPS valid response count, promoter, passive, and detractor counts and percentages, NPS, average NPS score, and the peak registration day. Use the correct fields and denominators. For every metric, give me the exact Excel formula I can paste to verify it, using my column letters A to L. Present the results in one table, then list anything you are not certain about. Do not build anything yet. Then stop. | G6: One table of KPIs with exact formulas that skip the blank NPS cells. It corrected its own NPS rounding (+23.9) and listed uncertainties honestly. One tied peak day (6 Dec and 11 Nov, 15 registrations each) cannot be returned by a single formula. | H6: I asked it to turn that table into a spreadsheet. | I6: Kept | J6: Sheet1!A1
A7: 4 | B7: 46267 | C7: Claude | D7: Claude | F7: Create a spreadsheet from your last answer. | G7: Added a "Baseline KPIs" sheet to a copy of my workbook with live formulas, independent check values, a match column and 0 formula errors. The first check for the MODE (peak day) result failed . | H7: I moved on to building the dashboard. This sheet later became "Baseline Validation". | I7: Kept | J7: Baseline Validation'!A1
A8: 5 | B8: 46267 | C8: Claude | D8: Claude | F8: Continue. Phase 3a, dashboard: Build a single-file React artifact containing the analytics dashboard. Include KPI cards (registrations, check-ins, no-shows, attendance rate, no-show rate, NPS with n), a registration trend chart over time, registrations by channel with attendance rate, attendance versus no-show by channel, and the NPS split. Add filters for channel, attendee type, and early bird, and a footer showing rows loaded = 500. Embed all 500 rows exactly as in the file, compute every figure in code without hard-coding totals, use React, Recharts, and Tailwind only, and never use localStorage. | G8: Produced a single React file with all 500 rows embedded and checked row by row against the sheet. Every figure is computed in code, and the filters and footer work. The look was plain, it was delivered as a .jsx file (not a hosted link), and it was not viewed in a real browser. | H8: I asked for a professional visual style without changing any numbers. | I8: Kept | J8: Sheet1!A38
A9: 6 | B9: 46267 | C9: Claude | D9: Claude | F9: Continue. Improvement round, visual styling: Improve the look of the dashboard only, and do not change any number, calculation, filter, or data. Replace the plain background with a soft, professional gradient, and keep the cards white or lightly tinted with rounded corners and soft shadows. Add a bold header band with the event name and a matching accent colour for each KPI card. Use one consistent, colour-blind-safe palette across all charts (attended always green, no-show always orange), and keep text contrast strong. Use only React, Recharts, and Tailwind core classes, with no localStorage. Afterwards, confirm the key numbers are unchanged (500 registrations, 433 check-ins, 67 no-shows, 86.6% attendance, 13.4% no-show, NPS +23.9 with n = 255). Then stop. | G9: Added a gradient background, header band, per-card accent colours and a colour-blind-safe palette. It rendered the component to confirm 500, 433, 67, 86.6%, 13.4% and +23.9 were unchanged. It slightly reworded the header text, needed dark labels on the light orange, and still did not check it in a real browser. | H9: I asked for the check-in screen. | I9: Kept | J9: Sheet1!A38
A10: 7 | B10: 46267 | C10: Claude | D10: Claude | F10: Continue. Phase 3b, check-in screen: Add a separate check-in page to the same artifact with clear navigation, without removing or damaging the dashboard. It needs one search bar for Registration ID or Attendee Name (partial, case-insensitive). Handle blank searches, no matches, and multiple matching names by listing every match with ID, city, attendee type, and status. Show the current checked-in status, with Check in and Undo buttons and a live "Checked in X / 450" counter. Do not double-count anyone. Use only fields available in the data. Then suggest 5 test searches I should try, including a duplicate name, an ID, a partial name, and a wrong name. Then stop. | G10: The check-in page handles blank, no-match and duplicate names (Pranav Joshi returns REG0031 and REG0044). The counter cannot double-count, and it gave 5 test searches. It also added things I had not asked for: a block at 450 and a Reset button. The dashboard did not yet reflect check-ins (found later). | H10: I asked it to independently verify the numbers and the filters. | I10: Kept | J10: Sheet1!A62
A11: 8 | B11: 46267 | C11: Claude | D11: Claude | F11: Continue. Phase 4, verification: Independently verify all important calculations against the original data. Recalculate total registrations, check-ins, no-shows, attendance rate, no-show rate, channel-level metrics, NPS counts, NPS percentage, and average NPS. Also test the filters by recalculating two filtered views (for example one channel only, and one attendee type only) and comparing them with what the app shows. Show a table with the app value, the recalculated value, and whether they match. If any discrepancy exists, identify the cause and correct the application rather than hiding or approximating the difference. Then stop. | G11: Ran the real app and compared 105 values with a recalculation from the xlsx, including the Instagram-only and Student-only views. All matched. Average NPS is not shown in the app, and it said so instead of hiding that. | H11: I asked for a strict audit and at least three improvement rounds. | I11: Kept | J11: Sheet1!A62
A12: 9 | B12: 46267 | C12: Claude | D12: Claude | F12: Continue. Phase 5, audit and improvement rounds: Perform a strict quality audit of the app against the original Task Brief, checking functionality, calculations, filters and search, navigation, visual clarity, consistency, data accuracy, usability, and completeness. Identify weaknesses, then perform at least three further explicit improvement rounds (not counting the earlier visual styling round). In each round, state what was wrong or could be improved, what evidence led to that conclusion, what change was made, and how the change was verified. Do not make cosmetic changes without a reason. Then stop | G12: Found concrete weaknesses with evidence and fixed them in 4 tested rounds. Filters and search reset when switching pages, the dashboard showed 433 while the counter showed 434, and the name "joshi pranav" returned 0 results. It added share of check-ins and 95% intervals per channel, and an NPS small-sample warning with average score. The answer was very long, and some changes (the dashboard toggle) were more than minimal. | H12: I decided I did not want Undo on the check-in page and asked for it to be removed. | I12: Kept | J12: Sheet1!A90
A13: 10 | B13: 46267 | C13: Claude | D13: Claude | F13: Remove the Undo button from the check-in page. Keep everything else exactly as it is, with no other changes to the check-in page, the dashboard, the calculations, or the data. | G13: Removed only the Undo button and tested that Check in, the counter and the dashboard still worked. It pointed out the consequence: a mistaken check-in could then only be reversed by the Reset-all button. | H13: I realised I still needed to correct one person's mistake, so I asked it to restore the previous version. | I13: Rejected | J13: Sheet1!A90
A14: 11 | B14: 46267 | C14: Claude | D14: Claude | F14: Revert to the previous version of the app, the one before the Undo button was removed. Restore the Undo button on the check-in page, and keep everything else exactly as it was, with no other changes to the dashboard, calculations, or data. | G14: Restored Undo and re-ran the tests: undo, re-check-in and the stop at 450 / 450 all work, and 35 of 35 dashboard checks matched. It had no saved copy of the earlier file, so it re-inserted the same code instead of restoring a file. | H14: I asked for the channel analysis. | I14: Kept | J14: Sheet1!A120
A15: 12 | B15: 46267 | C15: Claude | D15: Claude | F15: Continue. Phase 6, channel analysis: Use the actual heard_about_via field. For each channel, calculate registrations, check-ins, no-shows, attendance rate with a 95% confidence interval, no-show rate, NPS with n, average fee, and revenue, only where the data supports them. Test whether the differences in attendance between channels are statistically meaningful, and say plainly if they are not. Check whether any channel's result is driven by its mix of attendee types. Clearly distinguish between a channel generating many registrations and a channel generating strong attendance. Rank channels separately on volume, attendance rate, and revenue per registration. Do not claim causation from correlation. | G15: Full channel table with intervals, a chi-square test (p = 0.291, not significant), Holm-corrected pairwise tests, an attendee-type mix check (Faculty only 51.4% attendance), separate rankings and Excel steps. It tested the formulas in a temporary workbook. | H15: I asked for the marketing plan based on these results. | I15: Kept | J15: Channel Analysis'!A1
A16: 13 | B16: 46267 | C16: Claude | D16: Claude | F16: Continue. Phase 7, marketing plan: Write a data-driven marketing mix plan for next year's event. My planning assumption is a total marketing budget of ₹ 1 lakh, and the goal is to fill 450 seats with people who actually attend. Calculate how many attendees are needed and how many registrations are needed per channel using each channel's attendance rate. Then give a budget allocation per channel (percentage and targets), a timeline based on the registration curve and the 1 December early-bird deadline, segment-specific actions to reduce no-shows, KPIs to track, and three risks with mitigation. Tag every number as [DATA] if it comes from the workbook or [ASSUMPTION] if it does not, since there are no cost or spend figures in the data. Clearly distinguish calculated facts from recommendations. | G16: Gave 520 registrations needed (524 with channels rounded up), a budget split with DATA and ASSUMPTION tags, a timeline showing no rush before 1 Dec, segment actions, 3 risks and a 5-line summary. It admitted the per-channel registrations are just this year's scaled by 450/433, and that the split follows volume, not efficiency, because there is no cost data. | H16: I asked it to add the outputs to my workbook. | I16: Kept | J16: Marketing Plan'!A1
A17: 14 | B17: 46267 | C17: Claude | D17: Claude | F17: Continue. Add the outputs to the workbook: Take the uploaded workbook, keep all existing sheets unchanged, and add three new sheets: "Baseline Validation" (if not already added), "Channel Analysis" (the Phase 6 table, using live Excel formulas that reference the Registrations sheet, with the independent values beside them and a MATCH/MISMATCH column), and "Marketing Plan" (the Phase 7 allocation table with each number tagged DATA or ASSUMPTION, and the assumptions listed clearly) | G17: Added the three sheets with live formulas, independent values and MATCH columns, 0 formula errors, and the original sheets unchanged. | H17: It give me results. | I17: Kept | J17: All the 3 sheets added in my workbook.
A18: 15
A19: 16
A20: 17
A21: 18
A22: 19
A23: 20
A24: 21
A25: 22
A26: 23
A27: 24
A28: 25
A29: 26

Sheet Sheet1
E5: Evidence for Prompt 1
P6: Evidence for Prompt 2
E35: Evidence for Prompt 4 | N35: Evidence for Prompt 5
E59: Evidence for Prompt 6 | N59: Evidence for Prompt 7
E83: Evidence for Prompt 8 | N83: Evidence for Prompt 9
E110: Evidence for Prompt 10

Sheet Baseline Validation
A1: Baseline Validation: Phase 2 KPIs checked against independent values
A2: Green = live Excel formula on the Registrations sheet (rows 2-501). Blue = independent value computed separately in Python/pandas and typed in. Match? compares the two (tolerance 0.000001).
A3: Result | B3: =IF(COUNTIF(F6:F26,"MISMATCH")=0,"All "&COUNTIF(F6:F26,"MATCH")&" comparisons MATCH",COUNTIF(F6:F26,"MISMATCH")&" MISMATCH found") -> 1 MISMATCH found
A5: # | B5: Metric | C5: Live value (formula) | D5: Excel formula (text) | E5: Independent value | F5: MATCH / MISMATCH
A6: 1 | B6: Total registrations | C6: =COUNTA(Registrations!$A$2:$A$501) -> 500 | D6: =COUNTA(Registrations!$A$2:$A$501) -> 500 | E6: 500 | F6: =IF(ABS(C6-E6)<0.000001,"MATCH","MISMATCH") -> MATCH
A7: 2 | B7: Total check-ins (checked_in = Yes) | C7: =COUNTIF(Registrations!$J$2:$J$501,"Yes") -> 433 | D7: =COUNTIF(Registrations!$J$2:$J$501,"Yes") -> 433 | E7: 433 | F7: =IF(ABS(C7-E7)<0.000001,"MATCH","MISMATCH") -> MATCH
A8: 3 | B8: Total no-shows (checked_in = No) | C8: =COUNTIF(Registrations!$J$2:$J$501,"No") -> 67 | D8: =COUNTIF(Registrations!$J$2:$J$501,"No") | E8: 67 | F8: =IF(ABS(C8-E8)<0.000001,"MATCH","MISMATCH") -> MATCH
A9: 4 | B9: Attendance rate (Yes / total registrations) | C9: =COUNTIF(Registrations!$J$2:$J$501,"Yes")/COUNTA(Registrations!$A$2:$A$501) -> 0.866 | D9: =COUNTIF(Registrations!$J$2:$J$501,"Yes")/COUNTA(Registrations!$A$2:$A$501) | E9: 0.866 | F9: =IF(ABS(C9-E9)<0.000001,"MATCH","MISMATCH") -> MATCH
A10: 5 | B10: No-show rate (No / total registrations) | C10: =COUNTIF(Registrations!$J$2:$J$501,"No")/COUNTA(Registrations!$A$2:$A$501) -> 0.134 | D10: =COUNTIF(Registrations!$J$2:$J$501,"No")/COUNTA(Registrations!$A$2:$A$501) | E10: 0.134 | F10: =IF(ABS(C10-E10)<0.000001,"MATCH","MISMATCH") -> MATCH
A11: 6 | B11: Total revenue, all registrations (INR) | C11: =SUM(Registrations!$I$2:$I$501) -> 476481.4 | D11: =SUM(Registrations!$I$2:$I$501) | E11: 476481.4 | F11: =IF(ABS(C11-E11)<0.000001,"MATCH","MISMATCH") -> MATCH
A12: 6a | B12: Revenue, checked-in attendees only (INR) | C12: =SUMIFS(Registrations!$I$2:$I$501,Registrations!$J$2:$J$501,"Yes") -> 423926.6 | D12: =SUMIFS(Registrations!$I$2:$I$501,Registrations!$J$2:$J$501,"Yes") | E12: 423926.6 | F12: =IF(ABS(C12-E12)<0.000001,"MATCH","MISMATCH") -> MATCH
A13: 7 | B13: NPS valid response count (n) | C13: =COUNT(Registrations!$L$2:$L$501) -> 255 | D13: =COUNT(Registrations!$L$2:$L$501) | E13: 255 | F13: =IF(ABS(C13-E13)<0.000001,"MATCH","MISMATCH") -> MATCH
A14: 8 | B14: Promoters (9-10), count | C14: =COUNTIF(Registrations!$L$2:$L$501,">=9") -> 106 | D14: =COUNTIF(Registrations!$L$2:$L$501,">=9") | E14: 106 | F14: =IF(ABS(C14-E14)<0.000001,"MATCH","MISMATCH") -> MATCH
A15: 9 | B15: Passives (7-8), count | C15: =COUNTIFS(Registrations!$L$2:$L$501,">=7",Registrations!$L$2:$L$501,"<=8") -> 104 | D15: =COUNTIFS(Registrations!$L$2:$L$501,">=7",Registrations!$L$2:$L$501,"<=8") | E15: 104 | F15: =IF(ABS(C15-E15)<0.000001,"MATCH","MISMATCH") -> MATCH
A16: 10 | B16: Detractors (0-6), count | C16: =COUNTIFS(Registrations!$L$2:$L$501,">=0",Registrations!$L$2:$L$501,"<=6") -> 45 | D16: =COUNTIFS(Registrations!$L$2:$L$501,">=0",Registrations!$L$2:$L$501,"<=6") | E16: 45 | F16: =IF(ABS(C16-E16)<0.000001,"MATCH","MISMATCH") -> MATCH
A17: 11 | B17: Promoters % of valid | C17: =COUNTIF(Registrations!$L$2:$L$501,">=9")/COUNT(Registrations!$L$2:$L$501) -> 0.41568627 | D17: =COUNTIF(Registrations!$L$2:$L$501,">=9")/COUNT(Registrations!$L$2:$L$501) | E17: 0.41568627 | F17: =IF(ABS(C17-E17)<0.000001,"MATCH","MISMATCH") -> MATCH
A18: 12 | B18: Passives % of valid | C18: =COUNTIFS(Registrations!$L$2:$L$501,">=7",Registrations!$L$2:$L$501,"<=8")/COUNT(Registrations!$L$2:$L$501) -> 0.40784314 | D18: =COUNTIFS(Registrations!$L$2:$L$501,">=7",Registrations!$L$2:$L$501,"<=8")/COUNT(Registrations!$L$2:$L$501) | E18: 0.40784314 | F18: =IF(ABS(C18-E18)<0.000001,"MATCH","MISMATCH") -> MATCH
A19: 13 | B19: Detractors % of valid | C19: =COUNTIFS(Registrations!$L$2:$L$501,">=0",Registrations!$L$2:$L$501,"<=6")/COUNT(Registrations!$L$2:$L$501) -> 0.17647059 | D19: =COUNTIFS(Registrations!$L$2:$L$501,">=0",Registrations!$L$2:$L$501,"<=6")/COUNT(Registrations!$L$2:$L$501) | E19: 0.17647059 | F19: =IF(ABS(C19-E19)<0.000001,"MATCH","MISMATCH") -> MATCH
A20: 14 | B20: NPS (% Promoters - % Detractors, valid n only) | C20: =(COUNTIF(Registrations!$L$2:$L$501,">=9")-COUNTIFS(Registrations!$L$2:$L$501,">=0",Registrations!$L$2:$L$501,"<=6"))/COUNT(Registrations!$L$2:$L$501)*100 -> 23.921569 | D20: =(COUNTIF(Registrations!$L$2:$L$501,">=9")-COUNTIFS(Registrations!$L$2:$L$501,">=0",Registrations!$L$2:$L$501,"<=6"))/COUNT(Registrations!$L$2:$L$501)*100 | E20: 23.921569 | F20: =IF(ABS(C20-E20)<0.000001,"MATCH","MISMATCH") -> MATCH
A21: 15 | B21: Average NPS score (valid only) | C21: =AVERAGE(Registrations!$L$2:$L$501) -> 8 | D21: =AVERAGE(Registrations!$L$2:$L$501) | E21: 8 | F21: =IF(ABS(C21-E21)<0.000001,"MATCH","MISMATCH") -> MATCH
A22: 16 | B22: Peak registration day: highest daily count | C22: =SUMPRODUCT(MAX(COUNTIF(Registrations!$G$2:$G$501,Registrations!$G$2:$G$501))) -> 9 | D22: =SUMPRODUCT(MAX(COUNTIF(Registrations!$G$2:$G$501,Registrations!$G$2:$G$501))) | E22: 15 | F22: =IF(ABS(C22-E22)<0.000001,"MATCH","MISMATCH") -> MISMATCH
A23: 16a | B23: Peak day date from MODE (either tied date is valid) | C23: =MODE(Registrations!$G$2:$G$501) -> 45997 | D23: =MODE(Registrations!$G$2:$G$501) | E23: 6 Dec 2025 or 11 Nov 2025 | F23: =IF(OR(C23=DATE(2025,11,11),C23=DATE(2025,12,6)),"MATCH","MISMATCH") -> MATCH
A24: 16b | B24: Registrations on 6 Dec 2025 (tied peak) | C24: =COUNTIF(Registrations!$G$2:$G$501,DATE(2025,12,6)) -> 15 | D24: =COUNTIF(Registrations!$G$2:$G$501,DATE(2025,12,6)) | E24: 15 | F24: =IF(ABS(C24-E24)<0.000001,"MATCH","MISMATCH") -> MATCH
A25: 16c | B25: Registrations on 11 Nov 2025 (tied peak) | C25: =COUNTIF(Registrations!$G$2:$G$501,DATE(2025,11,11)) -> 15 | D25: =COUNTIF(Registrations!$G$2:$G$501,DATE(2025,11,11)) | E25: 15 | F25: =IF(ABS(C25-E25)<0.000001,"MATCH","MISMATCH") -> MATCH
A27: Integrity checks (each should read TRUE)
B28: Yes + No = total registrations | C28: =COUNTIF(Registrations!$J$2:$J$501,"Yes")+COUNTIF(Registrations!$J$2:$J$501,"No")=COUNTA(Registrations!$A$2:$A$501) -> TRUE
B29: Promoters + passives + detractors = n | C29: =COUNTIF(Registrations!$L$2:$L$501,">=9")+COUNTIFS(Registrations!$L$2:$L$501,">=7",Registrations!$L$2:$L$501,"<=8")+COUNTIFS(Registrations!$L$2:$L$501,">=0",Registrations!$L$2:$L$501,"<=6")=COUNT(Registrations!$L$2:$L$501) -> TRUE
B30: Attendance rate + no-show rate = 100% | C30: =ROUND(C9+C10,10)=1 -> TRUE
B31: Blank NPS cells = registrations - n (blanks never treated as 0) | C31: =COUNTBLANK(Registrations!$L$2:$L$501)=COUNTA(Registrations!$A$2:$A$501)-COUNT(Registrations!$L$2:$L$501) -> TRUE
B32: registration_id is unique (500 distinct) | C32: =SUMPRODUCT(1/COUNTIF(Registrations!$A$2:$A$501,Registrations!$A$2:$A$501))=COUNTA(Registrations!$A$2:$A$501) -> TRUE
A34: Notes
A35: - | B35: Definitions: attendance = Yes / total registrations; no-show = No / total registrations; NPS excludes blank scores from the denominator.
A36: - | B36: Peak registration day is a tie (15 registrations on each of 6 Dec 2025 and 11 Nov 2025). MODE returns only one of them, and which one can differ between Excel and other apps, so row 16a accepts either.
A37: - | B37: Total revenue assumes every registrant paid fee_paid_inr (no refund or payment-status field exists). Faculty count at INR 0.
A38: - | B38: Ranges are fixed to rows 2-501 (the current data extent); extend them if rows are added.

Sheet Channel Analysis
A1: Channel Analysis: heard_about_via (Phase 6)
A2: Section 1 = live formulas on Registrations. Section 3 compares each live value with an independent Python value (blue). Tolerance 0.000001. Revenue = sum of fee_paid_inr over all registrations (assumes everyone paid).
A3: Result | B3: =IF(COUNTIF(F31:F164,"MISMATCH")=0,"All "&COUNTIF(F31:F164,"MATCH")&" comparisons MATCH",COUNTIF(F31:F164,"MISMATCH")&" MISMATCH found") -> 7 MISMATCH found
A4: Channel | B4: Registrations | C4: Check-ins | D4: No-shows | E4: Attendance rate | F4: 95% CI low (Wilson)
A5: College mailer | B5: =COUNTIF(Registrations!$F$2:$F$501,$A5) -> 92 | C5: =COUNTIFS(Registrations!$F$2:$F$501,$A5,Registrations!$J$2:$J$501,"Yes") -> 81 | D5: =COUNTIFS(Registrations!$F$2:$F$501,$A5,Registrations!$J$2:$J$501,"No") -> 11 | E5: =C5/B5 -> 0.88043478 | F5: =((E5+1.96^2/(2*B5))-1.96*SQRT(E5*(1-E5)/B5+1.96^2/(4*B5^2)))/(1+1.96^2/B5) -> 0.79846243 | G5: =((E5+1.96^2/(2*B5))+1.96*SQRT(E5*(1-E5)/B5+1.96^2/(4*B5^2)))/(1+1.96^2/B5) -> 0.93190935 | H5: =D5/B5 -> 0.11956522 | I5: =C5/$C$11 -> 0.18706697 | J5: =COUNTIFS(Registrations!$F$2:$F$501,$A5,Registrations!$L$2:$L$501,">=0") -> 45 | K5: =COUNTIFS(Registrations!$F$2:$F$501,$A5,Registrations!$L$2:$L$501,">=9") -> 13 | L5: =COUNTIFS(Registrations!$F$2:$F$501,$A5,Registrations!$L$2:$L$501,">=0",Registrations!$L$2:$L$501,"<=6") -> 12 | M5: =IF(J5=0,"n/a",(K5-L5)/J5*100) -> 2.2222222 | N5: =AVERAGEIFS(Registrations!$I$2:$I$501,Registrations!$F$2:$F$501,$A5) -> 1003.4804 | O5: =SUMIFS(Registrations!$I$2:$I$501,Registrations!$F$2:$F$501,$A5) -> 92320.2 | P5: =SUMIFS(Registrations!$I$2:$I$501,Registrations!$F$2:$F$501,$A5,Registrations!$J$2:$J$501,"Yes") -> 83429.6 | Q5: =RANK(B5,$B$5:$B$10,0) -> 1 | R5: =RANK(C5,$C$5:$C$10,0) -> 1 | S5: =RANK(E5,$E$5:$E$10,0) -> 3 | T5: =RANK(N5,$N$5:$N$10,0) -> 2
A6: Friend referral | B6: =COUNTIF(Registrations!$F$2:$F$501,$A6) -> 87 | C6: =COUNTIFS(Registrations!$F$2:$F$501,$A6,Registrations!$J$2:$J$501,"Yes") -> 76 | D6: =COUNTIFS(Registrations!$F$2:$F$501,$A6,Registrations!$J$2:$J$501,"No") -> 11 | E6: =C6/B6 -> 0.87356322 | F6: =((E6+1.96^2/(2*B6))-1.96*SQRT(E6*(1-E6)/B6+1.96^2/(4*B6^2)))/(1+1.96^2/B6) -> 0.78762 | G6: =((E6+1.96^2/(2*B6))+1.96*SQRT(E6*(1-E6)/B6+1.96^2/(4*B6^2)))/(1+1.96^2/B6) -> 0.92791121 | H6: =D6/B6 -> 0.12643678 | I6: =C6/$C$11 -> 0.17551963 | J6: =COUNTIFS(Registrations!$F$2:$F$501,$A6,Registrations!$L$2:$L$501,">=0") -> 42 | K6: =COUNTIFS(Registrations!$F$2:$F$501,$A6,Registrations!$L$2:$L$501,">=9") -> 21 | L6: =COUNTIFS(Registrations!$F$2:$F$501,$A6,Registrations!$L$2:$L$501,">=0",Registrations!$L$2:$L$501,"<=6") -> 5 | M6: =IF(J6=0,"n/a",(K6-L6)/J6*100) -> 38.095238 | N6: =AVERAGEIFS(Registrations!$I$2:$I$501,Registrations!$F$2:$F$501,$A6) -> 1054.2966 | O6: =SUMIFS(Registrations!$I$2:$I$501,Registrations!$F$2:$F$501,$A6) -> 91723.8 | P6: =SUMIFS(Registrations!$I$2:$I$501,Registrations!$F$2:$F$501,$A6,Registrations!$J$2:$J$501,"Yes") -> 81732 | Q6: =RANK(B6,$B$5:$B$10,0) -> 3 | R6: =RANK(C6,$C$5:$C$10,0) -> 3 | S6: =RANK(E6,$E$5:$E$10,0) -> 4 | T6: =RANK(N6,$N$5:$N$10,0) -> 1
A7: Instagram | B7: =COUNTIF(Registrations!$F$2:$F$501,$A7) -> 77 | C7: =COUNTIFS(Registrations!$F$2:$F$501,$A7,Registrations!$J$2:$J$501,"Yes") -> 69 | D7: =COUNTIFS(Registrations!$F$2:$F$501,$A7,Registrations!$J$2:$J$501,"No") -> 8 | E7: =C7/B7 -> 0.8961039 | F7: =((E7+1.96^2/(2*B7))-1.96*SQRT(E7*(1-E7)/B7+1.96^2/(4*B7^2)))/(1+1.96^2/B7) -> 0.80815429 | G7: =((E7+1.96^2/(2*B7))+1.96*SQRT(E7*(1-E7)/B7+1.96^2/(4*B7^2)))/(1+1.96^2/B7) -> 0.94640772 | H7: =D7/B7 -> 0.1038961 | I7: =C7/$C$11 -> 0.15935335 | J7: =COUNTIFS(Registrations!$F$2:$F$501,$A7,Registrations!$L$2:$L$501,">=0") -> 42 | K7: =COUNTIFS(Registrations!$F$2:$F$501,$A7,Registrations!$L$2:$L$501,">=9") -> 17 | L7: =COUNTIFS(Registrations!$F$2:$F$501,$A7,Registrations!$L$2:$L$501,">=0",Registrations!$L$2:$L$501,"<=6") -> 6 | M7: =IF(J7=0,"n/a",(K7-L7)/J7*100) -> 26.190476 | N7: =AVERAGEIFS(Registrations!$I$2:$I$501,Registrations!$F$2:$F$501,$A7) -> 912.12727 | O7: =SUMIFS(Registrations!$I$2:$I$501,Registrations!$F$2:$F$501,$A7) -> 70233.8 | P7: =SUMIFS(Registrations!$I$2:$I$501,Registrations!$F$2:$F$501,$A7,Registrations!$J$2:$J$501,"Yes") -> 63639.2 | Q7: =RANK(B7,$B$5:$B$10,0) -> 5 | R7: =RANK(C7,$C$5:$C$10,0) -> 4 | S7: =RANK(E7,$E$5:$E$10,0) -> 1 | T7: =RANK(N7,$N$5:$N$10,0) -> 5
A8: LinkedIn | B8: =COUNTIF(Registrations!$F$2:$F$501,$A8) -> 77 | C8: =COUNTIFS(Registrations!$F$2:$F$501,$A8,Registrations!$J$2:$J$501,"Yes") -> 60 | D8: =COUNTIFS(Registrations!$F$2:$F$501,$A8,Registrations!$J$2:$J$501,"No") -> 17 | E8: =C8/B8 -> 0.77922078 | F8: =((E8+1.96^2/(2*B8))-1.96*SQRT(E8*(1-E8)/B8+1.96^2/(4*B8^2)))/(1+1.96^2/B8) -> 0.67456723 | G8: =((E8+1.96^2/(2*B8))+1.96*SQRT(E8*(1-E8)/B8+1.96^2/(4*B8^2)))/(1+1.96^2/B8) -> 0.85733714 | H8: =D8/B8 -> 0.22077922 | I8: =C8/$C$11 -> 0.13856813 | J8: =COUNTIFS(Registrations!$F$2:$F$501,$A8,Registrations!$L$2:$L$501,">=0") -> 44 | K8: =COUNTIFS(Registrations!$F$2:$F$501,$A8,Registrations!$L$2:$L$501,">=9") -> 20 | L8: =COUNTIFS(Registrations!$F$2:$F$501,$A8,Registrations!$L$2:$L$501,">=0",Registrations!$L$2:$L$501,"<=6") -> 7 | M8: =IF(J8=0,"n/a",(K8-L8)/J8*100) -> 29.545455 | N8: =AVERAGEIFS(Registrations!$I$2:$I$501,Registrations!$F$2:$F$501,$A8) -> 979.74026 | O8: =SUMIFS(Registrations!$I$2:$I$501,Registrations!$F$2:$F$501,$A8) -> 75440 | P8: =SUMIFS(Registrations!$I$2:$I$501,Registrations!$F$2:$F$501,$A8,Registrations!$J$2:$J$501,"Yes") -> 58651 | Q8: =RANK(B8,$B$5:$B$10,0) -> 5 | R8: =RANK(C8,$C$5:$C$10,0) -> 6 | S8: =RANK(E8,$E$5:$E$10,0) -> 6 | T8: =RANK(N8,$N$5:$N$10,0) -> 4
A9: Website | B9: =COUNTIF(Registrations!$F$2:$F$501,$A9) -> 79 | C9: =COUNTIFS(Registrations!$F$2:$F$501,$A9,Registrations!$J$2:$J$501,"Yes") -> 69 | D9: =COUNTIFS(Registrations!$F$2:$F$501,$A9,Registrations!$J$2:$J$501,"No") -> 10 | E9: =C9/B9 -> 0.87341772 | F9: =((E9+1.96^2/(2*B9))-1.96*SQRT(E9*(1-E9)/B9+1.96^2/(4*B9^2)))/(1+1.96^2/B9) -> 0.78243444 | G9: =((E9+1.96^2/(2*B9))+1.96*SQRT(E9*(1-E9)/B9+1.96^2/(4*B9^2)))/(1+1.96^2/B9) -> 0.92976812 | H9: =D9/B9 -> 0.12658228 | I9: =C9/$C$11 -> 0.15935335 | J9: =COUNTIFS(Registrations!$F$2:$F$501,$A9,Registrations!$L$2:$L$501,">=0") -> 41 | K9: =COUNTIFS(Registrations!$F$2:$F$501,$A9,Registrations!$L$2:$L$501,">=9") -> 21 | L9: =COUNTIFS(Registrations!$F$2:$F$501,$A9,Registrations!$L$2:$L$501,">=0",Registrations!$L$2:$L$501,"<=6") -> 6 | M9: =IF(J9=0,"n/a",(K9-L9)/J9*100) -> 36.585366 | N9: =AVERAGEIFS(Registrations!$I$2:$I$501,Registrations!$F$2:$F$501,$A9) -> 996.63291 | O9: =SUMIFS(Registrations!$I$2:$I$501,Registrations!$F$2:$F$501,$A9) -> 78734 | P9: =SUMIFS(Registrations!$I$2:$I$501,Registrations!$F$2:$F$501,$A9,Registrations!$J$2:$J$501,"Yes") -> 71841.4 | Q9: =RANK(B9,$B$5:$B$10,0) -> 4 | R9: =RANK(C9,$C$5:$C$10,0) -> 4 | S9: =RANK(E9,$E$5:$E$10,0) -> 5 | T9: =RANK(N9,$N$5:$N$10,0) -> 3
A10: WhatsApp group | B10: =COUNTIF(Registrations!$F$2:$F$501,$A10) -> 88 | C10: =COUNTIFS(Registrations!$F$2:$F$501,$A10,Registrations!$J$2:$J$501,"Yes") -> 78 | D10: =COUNTIFS(Registrations!$F$2:$F$501,$A10,Registrations!$J$2:$J$501,"No") -> 10 | E10: =C10/B10 -> 0.88636364 | F10: =((E10+1.96^2/(2*B10))-1.96*SQRT(E10*(1-E10)/B10+1.96^2/(4*B10^2)))/(1+1.96^2/B10) -> 0.80331255 | G10: =((E10+1.96^2/(2*B10))+1.96*SQRT(E10*(1-E10)/B10+1.96^2/(4*B10^2)))/(1+1.96^2/B10) -> 0.93709267 | H10: =D10/B10 -> 0.11363636 | I10: =C10/$C$11 -> 0.18013857 | J10: =COUNTIFS(Registrations!$F$2:$F$501,$A10,Registrations!$L$2:$L$501,">=0") -> 41 | K10: =COUNTIFS(Registrations!$F$2:$F$501,$A10,Registrations!$L$2:$L$501,">=9") -> 14 | L10: =COUNTIFS(Registrations!$F$2:$F$501,$A10,Registrations!$L$2:$L$501,">=0",Registrations!$L$2:$L$501,"<=6") -> 9 | M10: =IF(J10=0,"n/a",(K10-L10)/J10*100) -> 12.195122 | N10: =AVERAGEIFS(Registrations!$I$2:$I$501,Registrations!$F$2:$F$501,$A10) -> 773.06364 | O10: =SUMIFS(Registrations!$I$2:$I$501,Registrations!$F$2:$F$501,$A10) -> 68029.6 | P10: =SUMIFS(Registrations!$I$2:$I$501,Registrations!$F$2:$F$501,$A10,Registrations!$J$2:$J$501,"Yes") -> 64633.4 | Q10: =RANK(B10,$B$5:$B$10,0) -> 2 | R10: =RANK(C10,$C$5:$C$10,0) -> 2 | S10: =RANK(E10,$E$5:$E$10,0) -> 2 | T10: =RANK(N10,$N$5:$N$10,0) -> 6
A11: All channels | B11: =COUNTA(Registrations!$A$2:$A$501) -> 500 | C11: =COUNTIF(Registrations!$J$2:$J$501,"Yes") -> 433 | D11: =COUNTIF(Registrations!$J$2:$J$501,"No") -> 67 | E11: =C11/B11 -> 0.866 | F11: =((E11+1.96^2/(2*B11))-1.96*SQRT(E11*(1-E11)/B11+1.96^2/(4*B11^2)))/(1+1.96^2/B11) -> 0.83333333 | G11: =((E11+1.96^2/(2*B11))+1.96*SQRT(E11*(1-E11)/B11+1.96^2/(4*B11^2)))/(1+1.96^2/B11) -> 0.89308545 | H11: =D11/B11 -> 0.134 | I11: =C11/$C$11 -> 1 | J11: =COUNT(Registrations!$L$2:$L$501) -> 255 | K11: =COUNTIF(Registrations!$L$2:$L$501,">=9") -> 106 | L11: =COUNTIFS(Registrations!$L$2:$L$501,">=0",Registrations!$L$2:$L$501,"<=6") -> 45 | M11: =IF(J11=0,"n/a",(K11-L11)/J11*100) -> 23.921569 | N11: =AVERAGE(Registrations!$I$2:$I$501) -> 952.9628 | O11: =SUM(Registrations!$I$2:$I$501) -> 476481.4 | P11: =SUMIFS(Registrations!$I$2:$I$501,Registrations!$J$2:$J$501,"Yes") -> 423926.6
A13: Section 2: Are attendance differences between channels statistically meaningful? (chi-square test of independence, 6 channels x checked-in Yes/No)
A14: Channel | B14: Expected check-ins (if channel did not matter) | C14: Expected no-shows
A15: =A5 -> College mailer | B15: =B5*$C$11/$B$11 -> 79.672 | C15: =B5*$D$11/$B$11 -> 12.328
A16: =A6 -> Friend referral | B16: =B6*$C$11/$B$11 -> 75.342 | C16: =B6*$D$11/$B$11 -> 11.658
A17: =A7 -> Instagram | B17: =B7*$C$11/$B$11 -> 66.682 | C17: =B7*$D$11/$B$11 -> 10.318
A18: =A8 -> LinkedIn | B18: =B8*$C$11/$B$11 -> 66.682 | C18: =B8*$D$11/$B$11 -> 10.318
A19: =A9 -> Website | B19: =B9*$C$11/$B$11 -> 68.414 | C19: =B9*$D$11/$B$11 -> 10.586
A20: =A10 -> WhatsApp group | B20: =B10*$C$11/$B$11 -> 76.208 | C20: =B10*$D$11/$B$11 -> 11.792
A22: Chi-square p-value | B22: =CHITEST(C5:D10,B15:C20) -> 0.29112689
A23: Chi-square statistic | B23: =SUMPRODUCT((C5:D10-B15:C20)^2/B15:C20) -> 6.1582158
A24: Degrees of freedom | B24: =(ROWS(A5:A10)-1)*(2-1) -> 5
A25: Cramer's V (effect size) | B25: =SQRT(B23/B11) -> 0.11097942
A26: Smallest expected count (should be >= 5) | B26: =MIN(B15:C20) -> 10.318
A27: Reading | B27: =IF(B22<0.05,"Attendance differences between channels ARE statistically significant at 5%","Attendance differences between channels are NOT statistically significant at 5%") -> Attendance differences between channels are NOT statistically significant at 5%
A29: Section 3: Verification. Live formula value vs independent value (computed in Python/pandas/scipy and typed in)
A30: Channel | B30: Metric | C30: Live value (formula) | D30: Independent value | E30: Absolute difference | F30: MATCH / MISMATCH
A31: College mailer | B31: Registrations | C31: =B5 -> 92 | D31: 92 | E31: =ABS(C31-D31) -> 0 | F31: =IF(E31<0.000001,"MATCH","MISMATCH") -> MATCH
A32: College mailer | B32: Check-ins | C32: =C5 -> 81 | D32: 81 | E32: =ABS(C32-D32) -> 0 | F32: =IF(E32<0.000001,"MATCH","MISMATCH") -> MATCH
A33: College mailer | B33: No-shows | C33: =D5 -> 11 | D33: 11 | E33: =ABS(C33-D33) -> 0 | F33: =IF(E33<0.000001,"MATCH","MISMATCH") -> MATCH
A34: College mailer | B34: Attendance rate | C34: =E5 -> 0.88043478 | D34: 0.88043478 | E34: =ABS(C34-D34) -> 3.3306691e-16 | F34: =IF(E34<0.000001,"MATCH","MISMATCH") -> MATCH
A35: College mailer | B35: 95% CI low (Wilson) | C35: =F5 -> 0.79846243 | D35: 0.7984642 | E35: =ABS(C35-D35) -> 1.7763226e-06 | F35: =IF(E35<0.000001,"MATCH","MISMATCH") -> MISMATCH
A36: College mailer | B36: 95% CI high (Wilson) | C36: =G5 -> 0.93190935 | D36: 0.93190865 | E36: =ABS(C36-D36) -> 7.0044812e-07 | F36: =IF(E36<0.000001,"MATCH","MISMATCH") -> MATCH
A37: College mailer | B37: No-show rate | C37: =H5 -> 0.11956522 | D37: 0.11956522 | E37: =ABS(C37-D37) -> 3.469447e-16 | F37: =IF(E37<0.000001,"MATCH","MISMATCH") -> MATCH
A38: College mailer | B38: Share of all check-ins | C38: =I5 -> 0.18706697 | D38: 0.18706697 | E38: =ABS(C38-D38) -> 5.5511151e-17 | F38: =IF(E38<0.000001,"MATCH","MISMATCH") -> MATCH
A39: College mailer | B39: NPS valid n | C39: =J5 -> 45 | D39: 45 | E39: =ABS(C39-D39) -> 0 | F39: =IF(E39<0.000001,"MATCH","MISMATCH") -> MATCH
A40: College mailer | B40: Promoters (9-10) | C40: =K5 -> 13 | D40: 13 | E40: =ABS(C40-D40) -> 0 | F40: =IF(E40<0.000001,"MATCH","MISMATCH") -> MATCH
A41: College mailer | B41: Detractors (0-6) | C41: =L5 -> 12 | D41: 12 | E41: =ABS(C41-D41) -> 0 | F41: =IF(E41<0.000001,"MATCH","MISMATCH") -> MATCH
A42: College mailer | B42: NPS | C42: =M5 -> 2.2222222 | D42: 2.2222222 | E42: =ABS(C42-D42) -> 2.220446e-15 | F42: =IF(E42<0.000001,"MATCH","MISMATCH") -> MATCH
A43: College mailer | B43: Average fee (INR) = revenue per registration | C43: =N5 -> 1003.4804 | D43: 1003.4804 | E43: =ABS(C43-D43) -> 1.9326762e-12 | F43: =IF(E43<0.000001,"MATCH","MISMATCH") -> MATCH
...

Sheet Marketing Plan
A1: Marketing Plan: budget allocation for next year (Phase 7)
A2: Every number is tagged [DATA] (from this workbook, or arithmetic on workbook figures only) or [ASSUMPTION] (anything else, including the budget and any figure that depends on an input in Section A). The workbook has no cost or spend data.
A3: Result | B3: =IF(COUNTIF(E36:E53,"MISMATCH")=0,"All "&COUNTIF(E36:E53,"MATCH")&" comparisons MATCH",COUNTIF(E36:E53,"MISMATCH")&" MISMATCH found") -> All 18 comparisons MATCH
A4: # | B4: Assumption / input
A5: 1 | B5: Total marketing budget | C5: 100000 | D5: INR | E5: ASSUMPTION | F5: Given by you for the plan. The workbook contains no budget, cost or spend figures.
A6: 2 | B6: Seats to fill with attendees | C6: 450 | D6: seats | E6: DATA | F6: Event Info sheet, row 4: venue capacity 450. Assumes the same venue next year (ASSUMPTION).
A7: 3 | B7: Share of budget for the no-show programme (reminders, confirmations) | C7: 0.15 | D7: % of budget | E7: ASSUMPTION | F7: My recommendation; no data on what reminders cost.
A8: 4 | B8: Share of budget held as reserve (released at the T-33 checkpoint) | C8: 0.1 | D8: % of budget | E8: ASSUMPTION | F8: My recommendation, to reallocate once cost per attendee by channel is measured.
A9: 5 | B9: Share of budget for the six channels | C9: =1-C7-C8 -> 0.75 | D9: % of budget | E9: ASSUMPTION | F9: Formula: 100% less items 3 and 4.
A10: 6 | B10: Channel pool | C10: =C5*C9 -> 75000 | D10: INR | E10: ASSUMPTION | F10: Formula: budget x channel share.
A11: 7 | B11: Next year's registration window mirrors this year (opens T-63 days, early bird ends T-33, closes about T-4) | C11: n/a | D11: n/a | E11: ASSUMPTION | F11: Planning assumption stated in Phase 7.
A12: 8 | B12: Channel mix and each channel's attendance rate repeat this year's | C12: n/a | D12: n/a | E12: ASSUMPTION | F12: Planning assumption stated in Phase 7.
A13: 9 | B13: Budget is split in proportion to registrations needed per channel (no cost data, so no efficiency weighting) | C13: n/a | D13: n/a | E13: ASSUMPTION | F13: Planning assumption stated in Phase 7.
A14: 10 | B14: All registrants pay the fee in fee_paid_inr (no refund or payment-status field) | C14: n/a | D14: n/a | E14: ASSUMPTION | F14: Planning assumption stated in Phase 7.
A16: Section B: registrations needed and budget allocation (tags in the header and tag row)
A17: Channel | B17: Share of this year's check-ins [DATA] | C17: Attendee target [DATA] | D17: Attendance rate [DATA] | E17: Registrations needed [DATA] | F17: Registrations needed, rounded up [DATA] | G17: Cautious case: using 95% CI lower bound, rounded up [DATA] | H17: Share of required registrations [DATA] | I17: Budget (INR) [ASSUMPTION] | J17: % of total budget [ASSUMPTION] | K17: Budget per target attendee (INR) [ASSUMPTION]
A18: Tag | B18: DATA | C18: DATA | D18: DATA | E18: DATA | F18: DATA | G18: DATA | H18: DATA | I18: ASSUMPTION | J18: ASSUMPTION | K18: ASSUMPTION
A19: College mailer | B19: =INDEX('Channel Analysis'!$I$5:$I$10,MATCH($A19,'Channel Analysis'!$A$5:$A$10,0)) -> 0.18706697 | C19: =$C$6*B19 -> 84.180139 | D19: =INDEX('Channel Analysis'!$E$5:$E$10,MATCH($A19,'Channel Analysis'!$A$5:$A$10,0)) -> 0.88043478 | E19: =C19/D19 -> 95.612009 | F19: =ROUNDUP(E19,0) -> 96 | G19: =ROUNDUP(C19/INDEX('Channel Analysis'!$F$5:$F$10,MATCH($A19,'Channel Analysis'!$A$5:$A$10,0)),0) -> 106 | H19: =E19/$E$25 -> 0.184 | I19: =$C$10*H19 -> 13800 | J19: =I19/$C$5 -> 0.138 | K19: =I19/C19 -> 163.93416
A20: WhatsApp group | B20: =INDEX('Channel Analysis'!$I$5:$I$10,MATCH($A20,'Channel Analysis'!$A$5:$A$10,0)) -> 0.18013857 | C20: =$C$6*B20 -> 81.062356 | D20: =INDEX('Channel Analysis'!$E$5:$E$10,MATCH($A20,'Channel Analysis'!$A$5:$A$10,0)) -> 0.88636364 | E20: =C20/D20 -> 91.454965 | F20: =ROUNDUP(E20,0) -> 92 | G20: =ROUNDUP(C20/INDEX('Channel Analysis'!$F$5:$F$10,MATCH($A20,'Channel Analysis'!$A$5:$A$10,0)),0) -> 101 | H20: =E20/$E$25 -> 0.176 | I20: =$C$10*H20 -> 13200 | J20: =I20/$C$5 -> 0.132 | K20: =I20/C20 -> 162.83761
A21: Friend referral | B21: =INDEX('Channel Analysis'!$I$5:$I$10,MATCH($A21,'Channel Analysis'!$A$5:$A$10,0)) -> 0.17551963 | C21: =$C$6*B21 -> 78.983834 | D21: =INDEX('Channel Analysis'!$E$5:$E$10,MATCH($A21,'Channel Analysis'!$A$5:$A$10,0)) -> 0.87356322 | E21: =C21/D21 -> 90.415704 | F21: =ROUNDUP(E21,0) -> 91 | G21: =ROUNDUP(C21/INDEX('Channel Analysis'!$F$5:$F$10,MATCH($A21,'Channel Analysis'!$A$5:$A$10,0)),0) -> 101 | H21: =E21/$E$25 -> 0.174 | I21: =$C$10*H21 -> 13050 | J21: =I21/$C$5 -> 0.1305 | K21: =I21/C21 -> 165.22368
A22: Website | B22: =INDEX('Channel Analysis'!$I$5:$I$10,MATCH($A22,'Channel Analysis'!$A$5:$A$10,0)) -> 0.15935335 | C22: =$C$6*B22 -> 71.709007 | D22: =INDEX('Channel Analysis'!$E$5:$E$10,MATCH($A22,'Channel Analysis'!$A$5:$A$10,0)) -> 0.87341772 | E22: =C22/D22 -> 82.101617 | F22: =ROUNDUP(E22,0) -> 83 | G22: =ROUNDUP(C22/INDEX('Channel Analysis'!$F$5:$F$10,MATCH($A22,'Channel Analysis'!$A$5:$A$10,0)),0) -> 92 | H22: =E22/$E$25 -> 0.158 | I22: =$C$10*H22 -> 11850 | J22: =I22/$C$5 -> 0.1185 | K22: =I22/C22 -> 165.25121
A23: Instagram | B23: =INDEX('Channel Analysis'!$I$5:$I$10,MATCH($A23,'Channel Analysis'!$A$5:$A$10,0)) -> 0.15935335 | C23: =$C$6*B23 -> 71.709007 | D23: =INDEX('Channel Analysis'!$E$5:$E$10,MATCH($A23,'Channel Analysis'!$A$5:$A$10,0)) -> 0.8961039 | E23: =C23/D23 -> 80.023095 | F23: =ROUNDUP(E23,0) -> 81 | G23: =ROUNDUP(C23/INDEX('Channel Analysis'!$F$5:$F$10,MATCH($A23,'Channel Analysis'!$A$5:$A$10,0)),0) -> 89 | H23: =E23/$E$25 -> 0.154 | I23: =$C$10*H23 -> 11550 | J23: =I23/$C$5 -> 0.1155 | K23: =I23/C23 -> 161.06763
A24: LinkedIn | B24: =INDEX('Channel Analysis'!$I$5:$I$10,MATCH($A24,'Channel Analysis'!$A$5:$A$10,0)) -> 0.13856813 | C24: =$C$6*B24 -> 62.355658 | D24: =INDEX('Channel Analysis'!$E$5:$E$10,MATCH($A24,'Channel Analysis'!$A$5:$A$10,0)) -> 0.77922078 | E24: =C24/D24 -> 80.023095 | F24: =ROUNDUP(E24,0) -> 81 | G24: =ROUNDUP(C24/INDEX('Channel Analysis'!$F$5:$F$10,MATCH($A24,'Channel Analysis'!$A$5:$A$10,0)),0) -> 93 | H24: =E24/$E$25 -> 0.154 | I24: =$C$10*H24 -> 11550 | J24: =I24/$C$5 -> 0.1155 | K24: =I24/C24 -> 185.22778
A25: Channel pool (six channels) | B25: =SUM(B19:B24) -> 1 | C25: =SUM(C19:C24) -> 450 | D25: =SUM(C19:C24)/SUM(E19:E24) -> 0.866 | E25: =SUM(E19:E24) -> 519.63048 | F25: =SUM(F19:F24) -> 524 | G25: =SUM(G19:G24) -> 582 | H25: =SUM(H19:H24) -> 1 | I25: =SUM(I19:I24) -> 75000 | J25: =I25/$C$5 -> 0.75 | K25: =I25/C25 -> 166.66667
A26: No-show programme | I26: =$C$5*$C$7 -> 15000 | J26: =I26/$C$5 -> 0.15
A27: Reserve | I27: =$C$5*$C$8 -> 10000 | J27: =I27/$C$5 -> 0.1
A28: Total marketing budget | I28: =I25+I26+I27 -> 100000 | J28: =I28/$C$5 -> 1
A30: Pooled check: 450 attendees at the overall attendance rate, registrations needed (rounded up) [DATA] | B30: =ROUNDUP($C$6/'Channel Analysis'!E11,0) -> 520
A31: Overall budget per target attendee (INR) [ASSUMPTION] | B31: =$C$5/$C$6 -> 222.22222
A32: Overall budget per registration at the rounded-up target (INR) [ASSUMPTION] | B32: =$C$5/F25 -> 190.83969
A34: Section C: checks against independent values (computed in Python from the Registrations sheet; blue = typed)
A35: Item | B35: Live value (formula) | C35: Independent value | D35: Absolute difference | E35: MATCH / MISMATCH | F35: Note
A36: Budget: College mailer | B36: =I19 -> 13800 | C36: 13800 | D36: =ABS(B36-C36) -> 1.8189894e-12 | E36: =IF(D36<0.000001,"MATCH","MISMATCH") -> MATCH | F36: ASSUMPTION
A37: Budget: WhatsApp group | B37: =I20 -> 13200 | C37: 13200 | D37: =ABS(B37-C37) -> 3.6379788e-12 | E37: =IF(D37<0.000001,"MATCH","MISMATCH") -> MATCH | F37: ASSUMPTION
A38: Budget: Friend referral | B38: =I21 -> 13050 | C38: 13050 | D38: =ABS(B38-C38) -> 0 | E38: =IF(D38<0.000001,"MATCH","MISMATCH") -> MATCH | F38: ASSUMPTION
A39: Budget: Website | B39: =I22 -> 11850 | C39: 11850 | D39: =ABS(B39-C39) -> 0 | E39: =IF(D39<0.000001,"MATCH","MISMATCH") -> MATCH | F39: ASSUMPTION
A40: Budget: Instagram | B40: =I23 -> 11550 | C40: 11550 | D40: =ABS(B40-C40) -> 1.8189894e-12 | E40: =IF(D40<0.000001,"MATCH","MISMATCH") -> MATCH | F40: ASSUMPTION
A41: Budget: LinkedIn | B41: =I24 -> 11550 | C41: 11550 | D41: =ABS(B41-C41) -> 0 | E41: =IF(D41<0.000001,"MATCH","MISMATCH") -> MATCH | F41: ASSUMPTION
A42: Registrations needed (rounded up): College mailer | B42: =F19 -> 96 | C42: 96 | D42: =ABS(B42-C42) -> 0 | E42: =IF(D42<0.000001,"MATCH","MISMATCH") -> MATCH | F42: DATA
A43: Registrations needed (rounded up): WhatsApp group | B43: =F20 -> 92 | C43: 92 | D43: =ABS(B43-C43) -> 0 | E43: =IF(D43<0.000001,"MATCH","MISMATCH") -> MATCH | F43: DATA
...
